Workbook

Sheet Cover
A1: Fish Feeder 2026 Readiness Tracker
A2: Project governance, readiness progress and execution status
A4: CONTENTS | B4: PURPOSE
A5: Dashboard | B5: Executive view of overall progress, stage completion and priority actions
A6: Project Team | B6: Department owners for the Fish Feeder program
A7: FF_2026 | B7: Detailed part-level readiness tracker and milestone dates
A8: RACI Matrix | B8: Responsibility and accountability by readiness stage
A9: Timeline | B9: Program stage targets, dependencies and schedule status

Sheet Dashboard
A1: Fish Feeder 2026 — Readiness Dashboard
A2: ="Live view from FF_2026 • Updated "&TEXT(NOW(),"dd-mmm-yyyy hh:mm") -> Live view from FF_2026 • Updated 25-Sep-2026 15:14
A4: OVERALL PROGRESS | D4: TRACKED PARTS | G4: MECH PARTS | J4: HW PARTS | M4: PARTS WITH DELAY | P4: NEXT SOURCING TARGET
A5: =SUM(B14:B24)/SUM(C14:C24) -> 0.20283019 | D5: =COUNT(FF_2026!$A$3:$A$176) -> 106 | G5: =COUNTIF(FF_2026!H3:H1145,"Mech") -> 82 | J5: =COUNTIF(FF_2026!H3:H1145,"HW") -> 24 | M5: =COUNTIFS(FF_2026!$A$3:$A$176,"<>",FF_2026!$P$3:$P$176,">0")+COUNTIFS(FF_2026!$A$3:$A$176,"<>",FF_2026!$S$3:$S$176,">0")-COUNTIFS(FF_2026!$A$3:$A$176,"<>",FF_2026!$P$3:$P$176,">0",FF_2026!$S$3:$S$176,">0") -> 4 | P5: =IFERROR(MIN(FF_2026!$V$3:$V$176),"") -> 46280
A8: STORY IN BRIEF
A9: ="Overall gate progress is "&TEXT(A5,"0%")&" across "&TEXT(D5,"0")&" tracked parts. Design and part qualification are complete; sourcing is at "&TEXT(D18,"0%")&". Supplier qualification, sample procurement and factory handover remain at 0%, making downstream execution the critical path. "&TEXT(M5,"0")&" parts currently show a positive design or qualification delay." -> Overall gate progress is 20% across 106 tracked parts. Design and part qualification are complete; sourcing is at 16%. Supplier qualification, sample procurement and factory handover remain at 0%, making downstream execution the critical path. 4 parts currently show a positive design or qualification delay.
A12: READINESS STAGE PROGRESS
A13: Readiness Stage | B13: Completed | C13: Total | D13: Progress
A14: Design Readiness | B14: =COUNT(FF_2026!$M$3:$M$176) -> 93 | C14: =COUNT(FF_2026!$A$3:$A$176) -> 106 | D14: =IFERROR(B14/C14,0) -> 0.87735849
A16: Part Qualification | B16: =COUNT(FF_2026!$R$3:$R$176) -> 19 | C16: =COUNT(FF_2026!$A$3:$A$176) -> 106 | D16: =IFERROR(B16/C16,0) -> 0.17924528
A18: Sourcing Readiness | B18: =COUNT(FF_2026!$AD$3:$AD$176) -> 17 | C18: =COUNT(FF_2026!$A$3:$A$176) -> 106 | D18: =IFERROR(B18/C18,0) -> 0.16037736
A20: Supplier Qualification | B20: =COUNT(FF_2026!$AO$3:$AO$176) -> 0 | C20: =COUNT(FF_2026!$A$3:$A$176) -> 106 | D20: =IFERROR(B20/C20,0) -> 0
A22: Sample / Lot Procurement | B22: =COUNT(FF_2026!$AS$3:$AS$176) -> 0 | C22: =COUNT(FF_2026!$A$3:$A$176) -> 106 | D22: =IFERROR(B22/C22,0) -> 0
A24: Factory Handover | B24: =COUNT(FF_2026!$BC$3:$BC$176) -> 0 | C24: =COUNT(FF_2026!$A$3:$A$176) -> 106 | D24: =IFERROR(B24/C24,0) -> 0
A28: PARTS BY FUNCTION & CATEGORY — MATURITY PROGRESS
A29: Group | B29: ≥90% Maturity | C29: Total | D29: Progress
A30: ALL PARTS | B30: =COUNTIFS(FF_2026!$A$3:$A$646,"<>",FF_2026!$N$3:$N$646,">=0.9") -> 97 | C30: =$D$5 -> 106 | D30: =IFERROR(B30/C30,0) -> 0.91509434
A31: New - Critical | B31: =COUNTIFS(FF_2026!$G$3:$G$646,"New - Critical",FF_2026!$N$3:$N$646,">=0.9") -> 25 | C31: =COUNTIF(FF_2026!$G$3:$G$645,"New - Critical") -> 34 | D31: =IFERROR(B31/C31,0) -> 0.73529412
A32: New - Regular | B32: =COUNTIFS(FF_2026!$G$3:$G$646,"New - Regular",FF_2026!$N$3:$N$646,">=0.9") -> 0 | C32: =COUNTIF(FF_2026!$G$3:$G$645,"New - Regular") -> 0 | D32: =IFERROR(B32/C32,0) -> 0
A33: Carryover - Critical | B33: =COUNTIFS(FF_2026!$G$3:$G$646,"Carryover - Critical",FF_2026!$N$3:$N$646,">=0.9") -> 9 | C33: =COUNTIF(FF_2026!$G$3:$G$645,"Carryover - Critical") -> 9 | D33: =IFERROR(B33/C33,0) -> 1
A34: Carryover - Regular | B34: =COUNTIFS(FF_2026!$G$3:$G$646,"Carryover - Regular",FF_2026!$N$3:$N$646,">=0.9") -> 63 | C34: =COUNTIF(FF_2026!$G$3:$G$645,"Carryover - Regular") -> 63 | D34: =IFERROR(B34/C34,0) -> 1
A35: Not Specified | B35: =COUNTIFS(FF_2026!$A$3:$A$646,"<>",FF_2026!$G$3:$G$646,"",FF_2026!$N$3:$N$646,">=0.9") -> 0 | C35: =COUNTIFS(FF_2026!$A$3:$A$645,"<>",FF_2026!$G$3:$G$645,"") -> 0 | D35: =IFERROR(B35/C35,0) -> 0
A36: MECH | B36: =COUNTIFS(FF_2026!$H$3:$H$646,"Mech",FF_2026!$N$3:$N$646,">=0.9") -> 81 | C36: =COUNTIF(FF_2026!$H$3:$H$646,"Mech") -> 82 | D36: =IFERROR(B36/C36,0) -> 0.98780488
A37: New - Critical | B37: =COUNTIFS(FF_2026!$G$3:$G$646,"New - Critical",FF_2026!$H$3:$H$646,"Mech",FF_2026!$N$3:$N$646,">=0.9") -> 22 | C37: =COUNTIFS(FF_2026!$G$3:$G$646,"New - Critical",FF_2026!$H$3:$H$646,"Mech") -> 23 | D37: =IFERROR(B37/C37,0) -> 0.95652174
A38: New - Regular | B38: =COUNTIFS(FF_2026!$G$3:$G$646,"New - Regular",FF_2026!$H$3:$H$646,"Mech",FF_2026!$N$3:$N$646,">=0.9") -> 0 | C38: =COUNTIFS(FF_2026!$G$3:$G$646,"New - Regular",FF_2026!$H$3:$H$646,"Mech") -> 0 | D38: =IFERROR(B38/C38,0) -> 0
A39: Carryover - Critical | B39: =COUNTIFS(FF_2026!$G$3:$G$646,"Carryover - Critical",FF_2026!$H$3:$H$646,"Mech",FF_2026!$N$3:$N$646,">=0.9") -> 7 | C39: =COUNTIFS(FF_2026!$G$3:$G$646,"Carryover - Critical",FF_2026!$H$3:$H$646,"Mech") -> 7 | D39: =IFERROR(B39/C39,0) -> 1
A40: Carryover - Regular | B40: =COUNTIFS(FF_2026!$G$3:$G$646,"Carryover - Regular",FF_2026!$H$3:$H$646,"Mech",FF_2026!$N$3:$N$646,">=0.9") -> 52 | C40: =COUNTIFS(FF_2026!$G$3:$G$646,"Carryover - Regular",FF_2026!$H$3:$H$646,"Mech") -> 52 | D40: =IFERROR(B40/C40,0) -> 1
A41: Not Specified | B41: =COUNTIFS(FF_2026!$A$3:$A$646,"<>",FF_2026!$G$3:$G$646,"",FF_2026!$H$3:$H$646,"Mech",FF_2026!$N$3:$N$646,">=0.9") -> 0 | C41: =COUNTIFS(FF_2026!$A$3:$A$646,"<>",FF_2026!$G$3:$G$646,"",FF_2026!$H$3:$H$646,"Mech") -> 0 | D41: =IFERROR(B41/C41,0) -> 0
A42: HW | B42: =COUNTIFS(FF_2026!$H$3:$H$646,"HW",FF_2026!$N$3:$N$646,">=0.9") -> 16 | C42: =COUNTIF(FF_2026!$H$3:$H$646,"HW") -> 24 | D42: =IFERROR(B42/C42,0) -> 0.66666667
A43: New - Critical | B43: =COUNTIFS(FF_2026!$G$3:$G$646,"New - Critical",FF_2026!$H$3:$H$646,"HW",FF_2026!$N$3:$N$646,">=0.9") -> 3 | C43: =COUNTIFS(FF_2026!$G$3:$G$646,"New - Critical",FF_2026!$H$3:$H$646,"HW") -> 11 | D43: =IFERROR(B43/C43,0) -> 0.27272727
A44: New - Regular | B44: =COUNTIFS(FF_2026!$G$3:$G$646,"New - Regular",FF_2026!$H$3:$H$646,"HW",FF_2026!$N$3:$N$646,">=0.9") -> 0 | C44: =COUNTIFS(FF_2026!$G$3:$G$646,"New - Regular",FF_2026!$H$3:$H$646,"HW") -> 0 | D44: =IFERROR(B44/C44,0) -> 0
A45: Carryover - Critical | B45: =COUNTIFS(FF_2026!$G$3:$G$646,"Carryover - Critical",FF_2026!$H$3:$H$646,"HW",FF_2026!$N$3:$N$646,">=0.9") -> 2 | C45: =COUNTIFS(FF_2026!$G$3:$G$646,"Carryover - Critical",FF_2026!$H$3:$H$646,"HW") -> 2 | D45: =IFERROR(B45/C45,0) -> 1
A46: Carryover - Regular | B46: =COUNTIFS(FF_2026!$G$3:$G$646,"Carryover - Regular",FF_2026!$H$3:$H$646,"HW",FF_2026!$N$3:$N$646,">=0.9") -> 11 | C46: =COUNTIFS(FF_2026!$G$3:$G$646,"Carryover - Regular",FF_2026!$H$3:$H$646,"HW") -> 11 | D46: =IFERROR(B46/C46,0) -> 1
A47: Not Specified | B47: =COUNTIFS(FF_2026!$A$3:$A$646,"<>",FF_2026!$G$3:$G$646,"",FF_2026!$H$3:$H$646,"HW",FF_2026!$N$3:$N$646,">=0.9") -> 0 | C47: =COUNTIFS(FF_2026!$A$3:$A$646,"<>",FF_2026!$G$3:$G$646,"",FF_2026!$H$3:$H$646,"HW") -> 0 | D47: =IFERROR(B47/C47,0) -> 0
A48: FUNCTION NOT SPECIFIED | B48: =COUNTIFS(FF_2026!$A$3:$A$646,"<>",FF_2026!$H$3:$H$646,"",FF_2026!$N$3:$N$646,">=0.9") -> 0 | C48: =COUNTIFS(FF_2026!$A$3:$A$646,"<>",FF_2026!$H$3:$H$646,"") -> 0 | D48: =IFERROR(B48/C48,0) -> 0
A52: PRIORITY ACTIONS
A53: Priority | B53: Action
A54: 1 — New Critical | B54: New part with high complexity, longer sourcing lead time, higher qualification requirements, or other critical factors.
A55: 2 — New Regular | B55: New part with lower complexity, shorter sourcing lead time, and relatively straightforward qualification requirements.
A56: 3 — Carryover Critical | B56: Existing/carryover part with high complexity, longer sourcing lead time, higher qualification requirements, or other critical factors.
...

Sheet Project Team
A1: Department | B1: Fish Feeder
A2: Product Engineering | B2: Mallesha
A3: Design | B3: Ravindra Namburi
A4: HW | B4: Pavan K
A5: FW | B5: Prem
A6: Procurement | B6: Ravindra Kolla
A7: Quality | B7: Jeyamurgan
A8: Production | B8: Venu
A9: Customer Success | B9: Pavan N
A10: V&V | B10: Kiran

Sheet FF_2026_Ref_Backup
A1: Design Readiness | P1: Part Qualification Readiness | W1: Sourcing Readiness | AK1: Supplier Qualification | AP1: Sample / Lot Procurement | AU1: Factory Handover Rediness
A2: Sl.No | B2: PE Kick-off Date | C2: Part Number | D2: Part Discription | E2: Part Type | F2: Part Category | G2: Part Function | H2: BOM Rev. No | I2: Rev. No | J2: Qty | K2: Design Readiness Planned | L2: Design Readiness Actual | M2: Maturity % | N2: Doc. Rec'd | O2: Status (Days) | P2: PE Verif. Planned | Q2: PE Verif. Actual | R2: Status (Days) | S2: Ready for PQ | T2: Drawing / Spec to SCM | U2: Sourcing Target Date | V2: Comments/ Remarks | W2: Drawing / Spec to Vendors | X2: Vendors Identification Planned | Y2: Vendors Identification Actual | Z2: RFQ released | AA2: Technical queries closure | AB2: Quotations received | AC2: Vendor Finalization ((ToCo,) | AD2: Sample size | AE2: Lead Time Type | AF2: Lead time confirmation Planned | AG2: Lead time confirmation Actual | AH2: Release of PO | AI2: Status (Days) | AJ2: Remarks/ Comments | AK2: Vendor visit Required | AL2: PPAP/FAI (if applicable) | AM2: Sample approval | AN2: Quality & MF agreements | AO2: Remarks/ Comments | AP2: Samplet dispatch | AQ2: Sample receipt | AR2: QA (CFT) | AS2: Distpacth Sample to Design | AT2: Remarks/ Comments | AU2: Check Form & Fit | AV2: Testing | AW2: Open Issues | AX2: Design Changes | AY2: BOM revision updates | AZ2: Part Qualification Required | BA2: Part Approval | BB2: Remarks/ Comments
A3: 1 | B3: 46210 | C3: TBA | D3: H- Plate | E3: New | F3: New - Regular | G3: Mech | H3: 0 | J3: 1 | K3: 46211 | L3: 46211 | M3: 0.9 | N3: Yes | O3: =IF(OR(K3="",L3=""),"",SIGN(L3-K3)*(NETWORKDAYS(MIN(K3,L3),MAX(K3,L3))-1)) -> 0 | P3: 46233 | Q3: 46218 | R3: =IF(OR(P3="",Q3=""),"",SIGN(Q3-P3)*(NETWORKDAYS(MIN(P3,Q3),MAX(P3,Q3))-1)) -> -11 | S3: =IF(AND(M3>=90%,M3<=100%),"Yes","No") -> Yes | T3: 46234 | U3: 46280 | V3: Feedback from the Supplier - Jig/fixtures needed after samples finalisation before production they will make ready | W3: 46237 | X3: 46244 | Z3: 46238 | AA3: 46241 | AB3: 46241 | AC3: 46262 | AD3: 10 | AE3: Medium | AF3: =IF(OR(T3="",AE3=""),"",WORKDAY(T3,IF(AE3="Low",30,IF(AE3="Medium",45,IF(AE3="High",60,""))))) -> 46297 | AH3: 46266 | AI3: =IF(OR(U3="",AG3=""),"",SIGN(AG3-U3)*(NETWORKDAYS(MIN(U3,AG3),MAX(U3,AG3))-1)) | AJ3: 26th for approval submission
A4: 2 | B4: 46210 | C4: TBA | D4: Vertical Doser & Dispenser Structure | E4: New | F4: New - Critical | G4: Mech | H4: 0 | I4: A | J4: 1 | K4: 46211 | L4: 46233 | M4: 0.9 | N4: Yes | O4: =IF(OR(K4="",L4=""),"",SIGN(L4-K4)*(NETWORKDAYS(MIN(K4,L4),MAX(K4,L4))-1)) -> 16 | P4: 46233 | Q4: 46233 | R4: =IF(OR(P4="",Q4=""),"",SIGN(Q4-P4)*(NETWORKDAYS(MIN(P4,Q4),MAX(P4,Q4))-1)) -> 0 | S4: =IF(AND(M4>=90%,M4<=100%),"Yes","No") -> Yes | T4: 46234 | U4: 46280 | V4: Feedback from the Supplier - Jig/fixtures needed after samples finalisation before production they will make ready | W4: 46237 | X4: 46244 | Z4: 46238 | AA4: 46241 | AB4: 46241 | AC4: 46262 | AD4: 10 | AE4: Medium | AF4: =IF(OR(T4="",AE4=""),"",WORKDAY(T4,IF(AE4="Low",30,IF(AE4="Medium",45,IF(AE4="High",60,""))))) -> 46297 | AH4: 46266 | AI4: =IF(OR(U4="",AG4=""),"",SIGN(AG4-U4)*(NETWORKDAYS(MIN(U4,AG4),MAX(U4,AG4))-1))
A5: 3 | B5: 46210 | C5: TBA | D5: Vertical Doser top plate | E5: New | F5: New - Regular | G5: Mech | H5: 0 | J5: 1 | K5: 46211 | L5: 46211 | M5: 0.9 | N5: Yes | O5: =IF(OR(K5="",L5=""),"",SIGN(L5-K5)*(NETWORKDAYS(MIN(K5,L5),MAX(K5,L5))-1)) -> 0 | P5: 46233 | Q5: 46218 | R5: =IF(OR(P5="",Q5=""),"",SIGN(Q5-P5)*(NETWORKDAYS(MIN(P5,Q5),MAX(P5,Q5))-1)) -> -11 | S5: =IF(AND(M5>=90%,M5<=100%),"Yes","No") -> Yes | T5: 46234 | U5: 46280 | V5: Feedback from the Supplier - Jig/fixtures needed after samples finalisation before production they will make ready | W5: 46237 | X5: 46244 | Z5: 46238 | AA5: 46241 | AB5: 46241 | AC5: 46262 | AD5: 10 | AE5: Medium | AF5: =IF(OR(T5="",AE5=""),"",WORKDAY(T5,IF(AE5="Low",30,IF(AE5="Medium",45,IF(AE5="High",60,""))))) -> 46297 | AH5: 46266 | AI5: =IF(OR(U5="",AG5=""),"",SIGN(AG5-U5)*(NETWORKDAYS(MIN(U5,AG5),MAX(U5,AG5))-1))
A6: 4 | B6: 46210 | C6: TBA | D6: Vertical Doser bottom plate | E6: New | F6: New - Regular | G6: Mech | H6: 0 | I6: A | J6: 1 | K6: 46211 | L6: 46233 | M6: 0.9 | N6: Yes | O6: =IF(OR(K6="",L6=""),"",SIGN(L6-K6)*(NETWORKDAYS(MIN(K6,L6),MAX(K6,L6))-1)) -> 16 | P6: 46233 | Q6: 46233 | R6: =IF(OR(P6="",Q6=""),"",SIGN(Q6-P6)*(NETWORKDAYS(MIN(P6,Q6),MAX(P6,Q6))-1)) -> 0 | S6: =IF(AND(M6>=90%,M6<=100%),"Yes","No") -> Yes | T6: 46234 | U6: 46280 | V6: Feedback from the Supplier - Jig/fixtures needed after samples finalisation before production they will make ready | W6: 46237 | X6: 46244 | Z6: 46238 | AA6: 46241 | AB6: 46241 | AC6: 46262 | AD6: 10 | AE6: Medium | AF6: =IF(OR(T6="",AE6=""),"",WORKDAY(T6,IF(AE6="Low",30,IF(AE6="Medium",45,IF(AE6="High",60,""))))) -> 46297 | AH6: 46266 | AI6: =IF(OR(U6="",AG6=""),"",SIGN(AG6-U6)*(NETWORKDAYS(MIN(U6,AG6),MAX(U6,AG6))-1))
A7: 5 | B7: 46210 | C7: TBA | D7: Vertical doser Side Support | E7: New | F7: New - Regular | G7: Mech | H7: 0 | J7: 2 | K7: 46211 | L7: 46211 | M7: 0.9 | N7: Yes | O7: =IF(OR(K7="",L7=""),"",SIGN(L7-K7)*(NETWORKDAYS(MIN(K7,L7),MAX(K7,L7))-1)) -> 0 | P7: 46233 | Q7: 46218 | R7: =IF(OR(P7="",Q7=""),"",SIGN(Q7-P7)*(NETWORKDAYS(MIN(P7,Q7),MAX(P7,Q7))-1)) -> -11 | S7: =IF(AND(M7>=90%,M7<=100%),"Yes","No") -> Yes | T7: 46234 | U7: 46280 | V7: Feedback from the Supplier - Jig/fixtures needed after samples finalisation before production they will make ready | W7: 46237 | X7: 46244 | Z7: 46238 | AA7: 46241 | AB7: 46241 | AC7: 46262 | AD7: 10 | AE7: Medium | AF7: =IF(OR(T7="",AE7=""),"",WORKDAY(T7,IF(AE7="Low",30,IF(AE7="Medium",45,IF(AE7="High",60,""))))) -> 46297 | AH7: 46266 | AI7: =IF(OR(U7="",AG7=""),"",SIGN(AG7-U7)*(NETWORKDAYS(MIN(U7,AG7),MAX(U7,AG7))-1))
A8: 6 | B8: 46210 | C8: TBA | D8: Doser case | E8: New | F8: New - Regular | G8: Mech | H8: 0 | J8: 1 | K8: 46211 | L8: 46211 | M8: 0.9 | N8: Yes | O8: =IF(OR(K8="",L8=""),"",SIGN(L8-K8)*(NETWORKDAYS(MIN(K8,L8),MAX(K8,L8))-1)) -> 0 | P8: 46233 | Q8: 46218 | R8: =IF(OR(P8="",Q8=""),"",SIGN(Q8-P8)*(NETWORKDAYS(MIN(P8,Q8),MAX(P8,Q8))-1)) -> -11 | S8: =IF(AND(M8>=90%,M8<=100%),"Yes","No") -> Yes | T8: 46234 | U8: 46280 | W8: 46237 | X8: 46196 | Z8: 46238 | AA8: 46251 | AB8: 46251 | AC8: 46262 | AD8: 10 | AE8: Low | AF8: =IF(OR(T8="",AE8=""),"",WORKDAY(T8,IF(AE8="Low",30,IF(AE8="Medium",45,IF(AE8="High",60,""))))) -> 46276 | AH8: 46266 | AI8: =IF(OR(U8="",AG8=""),"",SIGN(AG8-U8)*(NETWORKDAYS(MIN(U8,AG8),MAX(U8,AG8))-1)) | AK8: 46286 | AO8: Visit Plan: 21–23 Sep; Tool Dev. Reports: Ravindra Namburi to provide.
A9: 7 | B9: 46210 | C9: TBA | D9: Doser motor holder | E9: New | F9: New - Critical | G9: Mech | H9: 0 | J9: 1 | K9: 46211 | L9: 46211 | M9: 0.9 | N9: Yes | O9: =IF(OR(K9="",L9=""),"",SIGN(L9-K9)*(NETWORKDAYS(MIN(K9,L9),MAX(K9,L9))-1)) -> 0 | P9: 46233 | Q9: 46218 | R9: =IF(OR(P9="",Q9=""),"",SIGN(Q9-P9)*(NETWORKDAYS(MIN(P9,Q9),MAX(P9,Q9))-1)) -> -11 | S9: =IF(AND(M9>=90%,M9<=100%),"Yes","No") -> Yes | T9: 46234 | U9: 46280 | W9: 46237 | X9: 46196 | Z9: 46238 | AA9: 46251 | AB9: 46251 | AC9: 46262 | AD9: 10 | AE9: Medium | AF9: =IF(OR(T9="",AE9=""),"",WORKDAY(T9,IF(AE9="Low",30,IF(AE9="Medium",45,IF(AE9="High",60,""))))) -> 46297 | AH9: 46266 | AI9: =IF(OR(U9="",AG9=""),"",SIGN(AG9-U9)*(NETWORKDAYS(MIN(U9,AG9),MAX(U9,AG9))-1)) | AK9: 46286
A10: 8 | B10: 46210 | C10: TBA | D10: Vertical doser wheel assembly | E10: New | F10: New - Critical | G10: Mech | H10: 0 | J10: 1 | K10: 46211 | L10: 46211 | M10: 0.9 | N10: Yes | O10: =IF(OR(K10="",L10=""),"",SIGN(L10-K10)*(NETWORKDAYS(MIN(K10,L10),MAX(K10,L10))-1)) -> 0 | P10: 46233 | Q10: 46218 | R10: =IF(OR(P10="",Q10=""),"",SIGN(Q10-P10)*(NETWORKDAYS(MIN(P10,Q10),MAX(P10,Q10))-1)) -> -11 | S10: =IF(AND(M10>=90%,M10<=100%),"Yes","No") -> Yes | T10: 46234 | U10: 46280 | W10: 46237 | X10: 46196 | Z10: 46238 | AA10: 46251 | AB10: 46251 | AC10: 46262 | AD10: 10 | AE10: Medium | AF10: =IF(OR(T10="",AE10=""),"",WORKDAY(T10,IF(AE10="Low",30,IF(AE10="Medium",45,IF(AE10="High",60,""))))) -> 46297 | AH10: 46266 | AI10: =IF(OR(U10="",AG10=""),"",SIGN(AG10-U10)*(NETWORKDAYS(MIN(U10,AG10),MAX(U10,AG10))-1)) | AK10: 46286
A11: 9 | B11: 46210 | C11: TBA | D11: Doser wheel insert | E11: New | F11: New - Critical | G11: Mech | H11: 0 | J11: 1 | K11: 46211 | L11: 46211 | M11: 0.9 | N11: Yes | O11: =IF(OR(K11="",L11=""),"",SIGN(L11-K11)*(NETWORKDAYS(MIN(K11,L11),MAX(K11,L11))-1)) -> 0 | P11: 46233 | Q11: 46218 | R11: =IF(OR(P11="",Q11=""),"",SIGN(Q11-P11)*(NETWORKDAYS(MIN(P11,Q11),MAX(P11,Q11))-1)) -> -11 | S11: =IF(AND(M11>=90%,M11<=100%),"Yes","No") -> Yes | T11: 46234 | U11: 46280 | W11: 46237 | X11: 46196 | Z11: 46238 | AA11: 46254 | AB11: 46251 | AC11: 46262 | AD11: 10 | AE11: Medium | AF11: =IF(OR(T11="",AE11=""),"",WORKDAY(T11,IF(AE11="Low",30,IF(AE11="Medium",45,IF(AE11="High",60,""))))) -> 46297 | AH11: 46266 | AI11: =IF(OR(U11="",AG11=""),"",SIGN(AG11-U11)*(NETWORKDAYS(MIN(U11,AG11),MAX(U11,AG11))-1)) | AK11: 46286
A12: 10 | B12: 46210 | C12: TBA | D12: Doser wheel | E12: New | F12: New - Critical | G12: Mech | H12: 0 | J12: 1 | K12: 46211 | L12: 46211 | M12: 0.9 | N12: Yes | O12: =IF(OR(K12="",L12=""),"",SIGN(L12-K12)*(NETWORKDAYS(MIN(K12,L12),MAX(K12,L12))-1)) -> 0 | P12: 46233 | Q12: 46218 | R12: =IF(OR(P12="",Q12=""),"",SIGN(Q12-P12)*(NETWORKDAYS(MIN(P12,Q12),MAX(P12,Q12))-1)) -> -11 | S12: =IF(AND(M12>=90%,M12<=100%),"Yes","No") -> Yes | T12: 46234 | U12: 46280 | W12: 46237 | X12: 46196 | Z12: 46238 | AA12: 46251 | AB12: 46251 | AC12: 46262 | AD12: 10 | AE12: Medium | AF12: =IF(OR(T12="",AE12=""),"",WORKDAY(T12,IF(AE12="Low",30,IF(AE12="Medium",45,IF(AE12="High",60,""))))) -> 46297 | AH12: 46266 | AI12: =IF(OR(U12="",AG12=""),"",SIGN(AG12-U12)*(NETWORKDAYS(MIN(U12,AG12),MAX(U12,AG12))-1)) | AK12: 46286
A13: 11 | B13: 46210 | C13: TBA | D13: Doser Wing nut | E13: New | F13: New - Critical | G13: Mech | H13: 0 | J13: 6 | K13: 46211 | L13: 46211 | M13: 0.9 | N13: Yes | O13: =IF(OR(K13="",L13=""),"",SIGN(L13-K13)*(NETWORKDAYS(MIN(K13,L13),MAX(K13,L13))-1)) -> 0 | P13: 46233 | Q13: 46218 | R13: =IF(OR(P13="",Q13=""),"",SIGN(Q13-P13)*(NETWORKDAYS(MIN(P13,Q13),MAX(P13,Q13))-1)) -> -11 | S13: =IF(AND(M13>=90%,M13<=100%),"Yes","No") -> Yes | T13: 46234 | U13: 46280 | W13: 46237 | X13: 46196 | Z13: 46238 | AA13: 46251 | AB13: 46251 | AC13: 46262 | AD13: 10 | AE13: Medium | AF13: =IF(OR(T13="",AE13=""),"",WORKDAY(T13,IF(AE13="Low",30,IF(AE13="Medium",45,IF(AE13="High",60,""))))) -> 46297 | AH13: 46266 | AI13: =IF(OR(U13="",AG13=""),"",SIGN(AG13-U13)*(NETWORKDAYS(MIN(U13,AG13),MAX(U13,AG13))-1)) | AK13: 46286
A14: 12 | B14: 46210 | C14: TBA | D14: Feed reducer | E14: New | F14: New - Critical | G14: Mech | H14: 0 | J14: 1 | K14: 46211 | L14: 46211 | M14: 0.9 | N14: Yes | O14: =IF(OR(K14="",L14=""),"",SIGN(L14-K14)*(NETWORKDAYS(MIN(K14,L14),MAX(K14,L14))-1)) -> 0 | P14: 46233 | Q14: 46218 | R14: =IF(OR(P14="",Q14=""),"",SIGN(Q14-P14)*(NETWORKDAYS(MIN(P14,Q14),MAX(P14,Q14))-1)) -> -11 | S14: =IF(AND(M14>=90%,M14<=100%),"Yes","No") -> Yes | T14: 46234 | U14: 46280 | W14: 46237 | X14: 46196 | Z14: 46238 | AA14: 46251 | AB14: 46251 | AC14: 46262 | AD14: 10 | AE14: Medium | AF14: =IF(OR(T14="",AE14=""),"",WORKDAY(T14,IF(AE14="Low",30,IF(AE14="Medium",45,IF(AE14="High",60,""))))) -> 46297 | AH14: 46266 | AI14: =IF(OR(U14="",AG14=""),"",SIGN(AG14-U14)*(NETWORKDAYS(MIN(U14,AG14),MAX(U14,AG14))-1)) | AK14: 46286
A15: 13 | B15: 46210 | C15: TBA | D15: Motor Protector | E15: New | F15: New - Regular | G15: Mech | H15: 0 | J15: 1 | K15: 46211 | L15: 46211 | M15: 0.9 | N15: Yes | O15: =IF(OR(K15="",L15=""),"",SIGN(L15-K15)*(NETWORKDAYS(MIN(K15,L15),MAX(K15,L15))-1)) -> 0 | P15: 46233 | Q15: 46218 | R15: =IF(OR(P15="",Q15=""),"",SIGN(Q15-P15)*(NETWORKDAYS(MIN(P15,Q15),MAX(P15,Q15))-1)) -> -11 | S15: =IF(AND(M15>=90%,M15<=100%),"Yes","No") -> Yes | T15: 46234 | U15: 46280 | W15: 46237 | X15: 46196 | Z15: 46238 | AA15: 46251 | AB15: 46251 | AC15: 46262 | AD15: 10 | AE15: Medium | AF15: =IF(OR(T15="",AE15=""),"",WORKDAY(T15,IF(AE15="Low",30,IF(AE15="Medium",45,IF(AE15="High",60,""))))) -> 46297 | AH15: 46266 | AI15: =IF(OR(U15="",AG15=""),"",SIGN(AG15-U15)*(NETWORKDAYS(MIN(U15,AG15),MAX(U15,AG15))-1)) | AK15: 46286
A16: 14 | B16: 46210 | C16: TBA | D16: Dosel wheel bearing | E16: New | F16: New - Critical | G16: Mech | H16: 0 | J16: 2 | K16: 46211 | L16: 46211 | M16: 0.9 | N16: Yes | O16: =IF(OR(K16="",L16=""),"",SIGN(L16-K16)*(NETWORKDAYS(MIN(K16,L16),MAX(K16,L16))-1)) -> 0 | P16: 46233 | Q16: 46218 | R16: =IF(OR(P16="",Q16=""),"",SIGN(Q16-P16)*(NETWORKDAYS(MIN(P16,Q16),MAX(P16,Q16))-1)) -> -11 | S16: =IF(AND(M16>=90%,M16<=100%),"Yes","No") -> Yes | T16: 46234 | U16: 46280 | V16: What is the warranty period confirmed by the selected supplier? - 24 months from manufacturing or 12 months from the date of installation whichever is the earlier. | W16: 46237 | X16: 46244 | Z16: 46239 | AA16: 46251 | AB16: 46251 | AC16: 46262 | AD16: 10 | AE16: Low | AF16: =IF(OR(T16="",AE16=""),"",WORKDAY(T16,IF(AE16="Low",30,IF(AE16="Medium",45,IF(AE16="High",60,""))))) -> 46276 | AH16: 46266 | AI16: =IF(OR(U16="",AG16=""),"",SIGN(AG16-U16)*(NETWORKDAYS(MIN(U16,AG16),MAX(U16,AG16))-1))
A17: 15 | B17: 46210 | C17: TBA | D17: Vertical doser Motor | E17: New | F17: New - Critical | G17: HW | H17: 0 | J17: 1 | K17: 46211 | L17: 46211 | M17: 0.8 | N17: Yes | O17: =IF(OR(K17="",L17=""),"",SIGN(L17-K17)*(NETWORKDAYS(MIN(K17,L17),MAX(K17,L17))-1)) -> 0 | P17: 46233 | Q17: 46218 | R17: =IF(OR(P17="",Q17=""),"",SIGN(Q17-P17)*(NETWORKDAYS(MIN(P17,Q17),MAX(P17,Q17))-1)) -> -11 | S17: =IF(AND(M17>=90%,M17<=100%),"Yes","No") -> No | T17: 46234 | U17: 46280 | V17: 24th Aug- Vendor discussion Open Points 1.Shaft to be changed to rust-proof material. 2.XT30 or XT60 connector with open-ended wire (male/female as required) 3.2 yrs warranty As of now information: 6 months 2nd Sep - 2026 For Model: RMCS-1211 – Industrial Grade IG45 Planetary DC Geared Motor, 50W, 10RPM, 12V, 186Kgcm, we have the following three options available: Option Construction 1 Electro-plated DC motor case + Stainless Steel gearbox case + Stainless Steel 304 gearbox shaft 2 Electro-plated DC motor case + Zinc-Nickel alloy plated gearbox case + Stainless Steel 304 gearbox shaft 3 Electro-plated DC motor case + Stainless Steel 304 gearbox shaft The above options differ mainly in the gearbox case material and construction. For complete technical specifications, please refer to the datasheet: https://download.robokits.co.in/downloads/rmcs_1211_datasheet_01.pdf Waiting for samples - 5 numbers | W17: 46237 | X17: 46244 | Z17: 46238 | AD17: 10 | AE17: High | AF17: =IF(OR(T17="",AE17=""),"",WORKDAY(T17,IF(AE17="Low",30,IF(AE17="Medium",45,IF(AE17="High",60,""))))) -> 46318 | AI17: =IF(OR(U17="",AG17=""),"",SIGN(AG17-U17)*(NETWORKDAYS(MIN(U17,AG17),MAX(U17,AG17))-1))
A18: 16 | B18: 46210 | C18: TBA | D18: Vertical doser feed stopper | E18: New | F18: New - Regular | G18: Mech | H18: 0 | J18: 1 | K18: 46211 | L18: 46211 | M18: 0.9 | N18: Yes | O18: =IF(OR(K18="",L18=""),"",SIGN(L18-K18)*(NETWORKDAYS(MIN(K18,L18),MAX(K18,L18))-1)) -> 0 | P18: 46233 | Q18: 46218 | R18: =IF(OR(P18="",Q18=""),"",SIGN(Q18-P18)*(NETWORKDAYS(MIN(P18,Q18),MAX(P18,Q18))-1)) -> -11 | S18: =IF(AND(M18>=90%,M18<=100%),"Yes","No") -> Yes | T18: 46234 | U18: 46280 | W18: 46237 | Z18: 46238 | AA18: 46241 | AB18: 46241 | AC18: 46262 | AD18: 10 | AE18: Low | AF18: =IF(OR(T18="",AE18=""),"",WORKDAY(T18,IF(AE18="Low",30,IF(AE18="Medium",45,IF(AE18="High",60,""))))) -> 46276 | AH18: 46266 | AI18: =IF(OR(U18="",AG18=""),"",SIGN(AG18-U18)*(NETWORKDAYS(MIN(U18,AG18),MAX(U18,AG18))-1))
A19: 17 | B19: 46210 | C19: TBA | D19: Feed Dispenser - (DISC) | E19: New | F19: New - Critical | G19: Mech | H19: 0 | I19: B | J19: 1 | K19: 46211 | L19: 46233 | M19: 0.9 | N19: Yes | O19: =IF(OR(K19="",L19=""),"",SIGN(L19-K19)*(NETWORKDAYS(MIN(K19,L19),MAX(K19,L19))-1)) -> 16 | P19: 46233 | Q19: 46233 | R19: =IF(OR(P19="",Q19=""),"",SIGN(Q19-P19)*(NETWORKDAYS(MIN(P19,Q19),MAX(P19,Q19))-1)) -> 0 | S19: =IF(AND(M19>=90%,M19<=100%),"Yes","No") -> Yes | T19: 46234 | U19: 46280 | V19: 6th Aug: Query from SCM: Feed dispenser – pipe details & source details of the product developed. 7th Aug: We will confirm the results of the thickness variation and power consumption tests on Monday. 12th Aug: Today rework will complete and Tomorrow test will be finished. 13th Aug: 14th Aug 2026 - will get details from design team 18th-Aug-2026: Received updated drawing and pipe details. MOQ: 40 tubes/pipes - 1800-2000 no's - supplier under working Note: If the XT30/XT60 -> The IP may fail. Pavan, could you please look into it once? | W19: 46237 | Z19: 46238 | AA19: 46252 | AD19: 10 | AE19: High | AF19: =IF(OR(T19="",AE19=""),"",WORKDAY(T19,IF(AE19="Low",30,IF(AE19="Medium",45,IF(AE19="High",60,""))))) -> 46318 | AI19: =IF(OR(U19="",AG19=""),"",SIGN(AG19-U19)*(NETWORKDAYS(MIN(U19,AG19),MAX(U19,AG19))-1))
A20: 18 | B20: 46210 | C20: TBA | D20: 12V Dispenser motor | E20: New | F20: New - Critical | G20: HW | H20: 0 | I20: A | J20: 1 | K20: 46211 | L20: 46239 | M20: 0.9 | N20: Yes | O20: =IF(OR(K20="",L20=""),"",SIGN(L20-K20)*(NETWORKDAYS(MIN(K20,L20),MAX(K20,L20))-1)) -> 20 | P20: 46233 | Q20: 46240 | R20: =IF(OR(P20="",Q20=""),"",SIGN(Q20-P20)*(NETWORKDAYS(MIN(P20,Q20),MAX(P20,Q20))-1)) -> 5 | S20: =IF(AND(M20>=90%,M20<=100%),"Yes","No") -> Yes | T20: 46234 | U20: 46280 | V20: HW Comments (30th July 2026): Motor procurement can start. Any cable modification can be carried out by a harness vendor. Timeline: Drawing will be ready by 4th Aug. Motor and cable. Along with an assembly drawing. Get the warrenty details | W20: 46237 | X20: 46244 | Z20: 46247 | AD20: 10 | AE20: High | AF20: =IF(OR(T20="",AE20=""),"",WORKDAY(T20,IF(AE20="Low",30,IF(AE20="Medium",45,IF(AE20="High",60,""))))) -> 46318 | AI20: =IF(OR(U20="",AG20=""),"",SIGN(AG20-U20)*(NETWORKDAYS(MIN(U20,AG20),MAX(U20,AG20))-1)) | AJ20: 1. Specification change may require new PN, setup, MOQ, and price revision. 2. Wire colours differ from their standard; Blue + Red combination can be provided for samples. 3. New shaft material has longer lead time, so sample timeline is not yet confirmed. 4. Current PN 10213 pricing is based on bulk availability. 5. Vendor needs MOQ and ordering schedule to proceed. 6. Stock available? - 20 No's
A21: 19 | B21: 46210 | C21: TBA | D21: Dispenser Motor holder | E21: New | F21: New - Regular | G21: Mech | H21: 0 | J21: 1 | K21: 46211 | L21: 46211 | M21: 0.9 | N21: Yes | O21: =IF(OR(K21="",L21=""),"",SIGN(L21-K21)*(NETWORKDAYS(MIN(K21,L21),MAX(K21,L21))-1)) -> 0 | P21: 46233 | Q21: 46218 | R21: =IF(OR(P21="",Q21=""),"",SIGN(Q21-P21)*(NETWORKDAYS(MIN(P21,Q21),MAX(P21,Q21))-1)) -> -11 | S21: =IF(AND(M21>=90%,M21<=100%),"Yes","No") -> Yes | T21: 46234 | U21: 46280 | W21: 46237 | X21: 46244 | Z21: 46238 | AA21: 46241 | AB21: 46241 | AC21: 46262 | AD21: 10 | AE21: Low | AF21: =IF(OR(T21="",AE21=""),"",WORKDAY(T21,IF(AE21="Low",30,IF(AE21="Medium",45,IF(AE21="High",60,""))))) -> 46276 | AH21: 46266 | AI21: =IF(OR(U21="",AG21=""),"",SIGN(AG21-U21)*(NETWORKDAYS(MIN(U21,AG21),MAX(U21,AG21))-1))
D30: XT-60 Male Connector
D31: Relay PCB
D32: Cable from PCB doser connector to relay PCB
D33: Inter connect cable from Relay PCB to PM PCB

Sheet FF_2026
A1: Design Readiness | Q1: Part Qualification Readiness | X1: Sourcing Readiness | AM1: Supplier Qualification | AR1: Sample / Lot Procurement | AW1: Factory Handover Rediness
A2: Sl.No | B2: PE Kick-off Date | C2: Part Number | D2: Part Discription | E2: Part Type | F2: Scope | G2: Part Category | H2: Part Function | I2: BOM Rev. No | J2: Rev. No | K2: Qty | L2: Design Readiness Planned | M2: Design Readiness Actual | N2: Maturity % | O2: Doc. Rec'd | P2: Status (Days) | Q2: PE Verif. Planned | R2: PE Verif. Actual | S2: Status (Days) | T2: Ready for PQ | U2: Drawing / Spec to SCM | V2: Sourcing Target Date | W2: Comments/ Remarks | X2: Drawing / Spec to Vendors | Y2: RFQ released | Z2: Vendors Identification Planned | AA2: Technical queries closure | AB2: Vendors Identification Actual | AC2: Quotations received | AD2: Vendor Finalization ((ToCo,) | AE2: Shortlisted Supplier Name | AF2: Sample size | AG2: Release of PO | AH2: Lead Time Type | AI2: Lead time confirmation Planned | AJ2: Lead time confirmation Actual | AK2: Status (Days) | AL2: Remarks/ Comments | AM2: Vendor visit Required | AN2: PPAP/FAI (if applicable) | AO2: Sample approval | AP2: Quality & MF agreements | AQ2: Remarks/ Comments | AR2: Samplet dispatch | AS2: Sample receipt | AT2: QA (CFT) | AU2: Distpacth Sample to Design | AV2: Remarks/ Comments | AW2: Check Form & Fit | AX2: Testing | AY2: Open Issues | AZ2: Design Changes | BA2: BOM revision updates | BB2: Part Qualification Required | BC2: Part Approval | BD2: Remarks/ Comments
A3: 1 | B3: 46210 | C3: TBA | D3: PM125 SQ- Float Version | E3: New | F3: Eruvaka | G3: New - Critical | H3: Mech | I3: r1 | K3: 1 | L3: 46211 | N3: 0.95 | P3: =IF(OR(L3="",M3=""),"",SIGN(M3-L3)*(NETWORKDAYS(MIN(L3,M3),MAX(L3,M3))-1)) | S3: =IF(OR(Q3="",R3=""),"",SIGN(R3-Q3)*(NETWORKDAYS(MIN(Q3,R3),MAX(Q3,R3))-1)) | T3: =IF(AND(N3>=90%,N3<=100%),"Yes","No") -> Yes | AF3: 10 | AK3: =IF(OR(AI3="",AJ3=""),"",SIGN(AJ3-AI3)*(NETWORKDAYS(MIN(AI3,AJ3),MAX(AI3,AJ3))-1))
A4: 2 | B4: 46210 | C4: ERLPM04 | D4: SQ125 Structure Assy | E4: Carryover | F4: Eruvaka | G4: Carryover - Critical | H4: Mech | I4: r1 | K4: 1 | L4: 46211 | M4: 46211 | N4: 1 | P4: =IF(OR(L4="",M4=""),"",SIGN(M4-L4)*(NETWORKDAYS(MIN(L4,M4),MAX(L4,M4))-1)) -> 0 | S4: =IF(OR(Q4="",R4=""),"",SIGN(R4-Q4)*(NETWORKDAYS(MIN(Q4,R4),MAX(Q4,R4))-1)) | T4: =IF(AND(N4>=90%,N4<=100%),"Yes","No") -> Yes | AF4: 10 | AK4: =IF(OR(AI4="",AJ4=""),"",SIGN(AJ4-AI4)*(NETWORKDAYS(MIN(AI4,AJ4),MAX(AI4,AJ4))-1))
A5: 3 | B5: 46210 | C5: ER790 | D5: SQ125 Spider | E5: Carryover | F5: Eruvaka | G5: Carryover - Critical | H5: Mech | I5: r1 | K5: 1 | L5: 46211 | M5: 46211 | N5: 1 | P5: =IF(OR(L5="",M5=""),"",SIGN(M5-L5)*(NETWORKDAYS(MIN(L5,M5),MAX(L5,M5))-1)) -> 0 | S5: =IF(OR(Q5="",R5=""),"",SIGN(R5-Q5)*(NETWORKDAYS(MIN(Q5,R5),MAX(Q5,R5))-1)) | T5: =IF(AND(N5>=90%,N5<=100%),"Yes","No") -> Yes | AF5: 10 | AK5: =IF(OR(AI5="",AJ5=""),"",SIGN(AJ5-AI5)*(NETWORKDAYS(MIN(AI5,AJ5),MAX(AI5,AJ5))-1))
A6: 4 | B6: 46210 | C6: ER791 | D6: SQ125 Pipe | E6: Carryover | F6: Eruvaka | G6: Carryover - Critical | H6: Mech | I6: r1 | K6: 4 | L6: 46211 | M6: 46211 | N6: 1 | P6: =IF(OR(L6="",M6=""),"",SIGN(M6-L6)*(NETWORKDAYS(MIN(L6,M6),MAX(L6,M6))-1)) -> 0 | S6: =IF(OR(Q6="",R6=""),"",SIGN(R6-Q6)*(NETWORKDAYS(MIN(Q6,R6),MAX(Q6,R6))-1)) | T6: =IF(AND(N6>=90%,N6<=100%),"Yes","No") -> Yes | AF6: 10 | AK6: =IF(OR(AI6="",AJ6=""),"",SIGN(AJ6-AI6)*(NETWORKDAYS(MIN(AI6,AJ6),MAX(AI6,AJ6))-1))
A7: 5 | B7: 46210 | C7: ER792 | D7: SQ125 H Structure | E7: Carryover | F7: Eruvaka | G7: Carryover - Critical | H7: Mech | I7: r1 | K7: 1 | L7: 46211 | M7: 46211 | N7: 1 | P7: =IF(OR(L7="",M7=""),"",SIGN(M7-L7)*(NETWORKDAYS(MIN(L7,M7),MAX(L7,M7))-1)) -> 0 | S7: =IF(OR(Q7="",R7=""),"",SIGN(R7-Q7)*(NETWORKDAYS(MIN(Q7,R7),MAX(Q7,R7))-1)) | T7: =IF(AND(N7>=90%,N7<=100%),"Yes","No") -> Yes | AF7: 10 | AK7: =IF(OR(AI7="",AJ7=""),"",SIGN(AJ7-AI7)*(NETWORKDAYS(MIN(AI7,AJ7),MAX(AI7,AJ7))-1))
A8: 6 | B8: 46210 | C8: ERFS072 | D8: M8 X 55 Hex head bolt | E8: Carryover | F8: Eruvaka | G8: Carryover - Regular | H8: Mech | I8: r1 | K8: =16+2+2 -> 20 | L8: 46211 | M8: 46211 | N8: 1 | P8: =IF(OR(L8="",M8=""),"",SIGN(M8-L8)*(NETWORKDAYS(MIN(L8,M8),MAX(L8,M8))-1)) -> 0 | S8: =IF(OR(Q8="",R8=""),"",SIGN(R8-Q8)*(NETWORKDAYS(MIN(Q8,R8),MAX(Q8,R8))-1)) | T8: =IF(AND(N8>=90%,N8<=100%),"Yes","No") -> Yes | AF8: 10 | AK8: =IF(OR(AI8="",AJ8=""),"",SIGN(AJ8-AI8)*(NETWORKDAYS(MIN(AI8,AJ8),MAX(AI8,AJ8))-1))
A9: 7 | B9: 46210 | C9: ERFS018 | D9: M8 Washer | E9: Carryover | F9: Eruvaka | G9: Carryover - Regular | H9: Mech | I9: r1 | K9: =32+4+8+4+2 -> 50 | L9: 46211 | M9: 46211 | N9: 1 | P9: =IF(OR(L9="",M9=""),"",SIGN(M9-L9)*(NETWORKDAYS(MIN(L9,M9),MAX(L9,M9))-1)) -> 0 | S9: =IF(OR(Q9="",R9=""),"",SIGN(R9-Q9)*(NETWORKDAYS(MIN(Q9,R9),MAX(Q9,R9))-1)) | T9: =IF(AND(N9>=90%,N9<=100%),"Yes","No") -> Yes | AF9: 10 | AK9: =IF(OR(AI9="",AJ9=""),"",SIGN(AJ9-AI9)*(NETWORKDAYS(MIN(AI9,AJ9),MAX(AI9,AJ9))-1))
A10: 8 | B10: 46210 | C10: ERFS020 | D10: M8 Nut | E10: Carryover | F10: Eruvaka | G10: Carryover - Regular | H10: Mech | I10: r1 | K10: =16+4+4+2+2 -> 28 | L10: 46211 | M10: 46211 | N10: 1 | P10: =IF(OR(L10="",M10=""),"",SIGN(M10-L10)*(NETWORKDAYS(MIN(L10,M10),MAX(L10,M10))-1)) -> 0 | S10: =IF(OR(Q10="",R10=""),"",SIGN(R10-Q10)*(NETWORKDAYS(MIN(Q10,R10),MAX(Q10,R10))-1)) | T10: =IF(AND(N10>=90%,N10<=100%),"Yes","No") -> Yes | AF10: 10 | AK10: =IF(OR(AI10="",AJ10=""),"",SIGN(AJ10-AI10)*(NETWORKDAYS(MIN(AI10,AJ10),MAX(AI10,AJ10))-1))
A11: 9 | B11: 46210 | C11: ERPA018 | D11: Strech film | E11: Carryover | F11: Eruvaka | G11: Carryover - Regular | H11: Mech | I11: r1 | K11: =200+40+100 -> 340 | L11: 46211 | M11: 46211 | N11: 1 | P11: =IF(OR(L11="",M11=""),"",SIGN(M11-L11)*(NETWORKDAYS(MIN(L11,M11),MAX(L11,M11))-1)) -> 0 | S11: =IF(OR(Q11="",R11=""),"",SIGN(R11-Q11)*(NETWORKDAYS(MIN(Q11,R11),MAX(Q11,R11))-1)) | T11: =IF(AND(N11>=90%,N11<=100%),"Yes","No") -> Yes | AF11: 10 | AK11: =IF(OR(AI11="",AJ11=""),"",SIGN(AJ11-AI11)*(NETWORKDAYS(MIN(AI11,AJ11),MAX(AI11,AJ11))-1))
A12: 10 | B12: 46210 | C12: ERPA008 | D12: Strech film | E12: Carryover | F12: Eruvaka | G12: Carryover - Regular | H12: Mech | I12: r1 | K12: 100 | L12: 46211 | M12: 46211 | N12: 1 | P12: =IF(OR(L12="",M12=""),"",SIGN(M12-L12)*(NETWORKDAYS(MIN(L12,M12),MAX(L12,M12))-1)) -> 0 | S12: =IF(OR(Q12="",R12=""),"",SIGN(R12-Q12)*(NETWORKDAYS(MIN(Q12,R12),MAX(Q12,R12))-1)) | T12: =IF(AND(N12>=90%,N12<=100%),"Yes","No") -> Yes | AF12: 10 | AK12: =IF(OR(AI12="",AJ12=""),"",SIGN(AJ12-AI12)*(NETWORKDAYS(MIN(AI12,AJ12),MAX(AI12,AJ12))-1))
A13: 11 | B13: 46210 | C13: ERLPM05 | D13: SQ125 Hopper Assembly | E13: Carryover | F13: Eruvaka | G13: Carryover - Regular | H13: Mech | I13: r1 | K13: 1 | L13: 46211 | M13: 46211 | N13: 1 | P13: =IF(OR(L13="",M13=""),"",SIGN(M13-L13)*(NETWORKDAYS(MIN(L13,M13),MAX(L13,M13))-1)) -> 0 | S13: =IF(OR(Q13="",R13=""),"",SIGN(R13-Q13)*(NETWORKDAYS(MIN(Q13,R13),MAX(Q13,R13))-1)) | T13: =IF(AND(N13>=90%,N13<=100%),"Yes","No") -> Yes | AF13: 10 | AK13: =IF(OR(AI13="",AJ13=""),"",SIGN(AJ13-AI13)*(NETWORKDAYS(MIN(AI13,AJ13),MAX(AI13,AJ13))-1))
A14: 12 | B14: 46210 | C14: ER785 | D14: SQ125 Square Hopper | E14: Carryover | F14: Eruvaka | G14: Carryover - Critical | H14: Mech | I14: r1 | K14: 1 | L14: 46211 | M14: 46211 | N14: 1 | P14: =IF(OR(L14="",M14=""),"",SIGN(M14-L14)*(NETWORKDAYS(MIN(L14,M14),MAX(L14,M14))-1)) -> 0 | S14: =IF(OR(Q14="",R14=""),"",SIGN(R14-Q14)*(NETWORKDAYS(MIN(Q14,R14),MAX(Q14,R14))-1)) | T14: =IF(AND(N14>=90%,N14<=100%),"Yes","No") -> Yes | AF14: 10 | AK14: =IF(OR(AI14="",AJ14=""),"",SIGN(AJ14-AI14)*(NETWORKDAYS(MIN(AI14,AJ14),MAX(AI14,AJ14))-1))
A15: 13 | B15: 46210 | C15: ER828 | D15: Pre-Mould Eruvaka Logo | E15: Carryover | F15: Eruvaka | G15: Carryover - Regular | H15: Mech | I15: r1 | K15: 1 | L15: 46211 | M15: 46211 | N15: 1 | P15: =IF(OR(L15="",M15=""),"",SIGN(M15-L15)*(NETWORKDAYS(MIN(L15,M15),MAX(L15,M15))-1)) -> 0 | S15: =IF(OR(Q15="",R15=""),"",SIGN(R15-Q15)*(NETWORKDAYS(MIN(Q15,R15),MAX(Q15,R15))-1)) | T15: =IF(AND(N15>=90%,N15<=100%),"Yes","No") -> Yes | AF15: 10 | AK15: =IF(OR(AI15="",AJ15=""),"",SIGN(AJ15-AI15)*(NETWORKDAYS(MIN(AI15,AJ15),MAX(AI15,AJ15))-1))
A16: 14 | B16: 46210 | C16: ER829 | D16: Pre-Mould Eruvaka Text - Blue | E16: Carryover | F16: Eruvaka | G16: Carryover - Regular | H16: Mech | I16: r1 | K16: 1 | L16: 46211 | M16: 46211 | N16: 1 | P16: =IF(OR(L16="",M16=""),"",SIGN(M16-L16)*(NETWORKDAYS(MIN(L16,M16),MAX(L16,M16))-1)) -> 0 | S16: =IF(OR(Q16="",R16=""),"",SIGN(R16-Q16)*(NETWORKDAYS(MIN(Q16,R16),MAX(Q16,R16))-1)) | T16: =IF(AND(N16>=90%,N16<=100%),"Yes","No") -> Yes | AF16: 10 | AK16: =IF(OR(AI16="",AJ16=""),"",SIGN(AJ16-AI16)*(NETWORKDAYS(MIN(AI16,AJ16),MAX(AI16,AJ16))-1))
A17: 15 | B17: 46210 | C17: ER830 | D17: Pre-Mould PondMother - Blue | E17: Carryover | F17: Eruvaka | G17: Carryover - Regular | H17: Mech | I17: r1 | K17: 1 | L17: 46211 | M17: 46211 | N17: 1 | P17: =IF(OR(L17="",M17=""),"",SIGN(M17-L17)*(NETWORKDAYS(MIN(L17,M17),MAX(L17,M17))-1)) -> 0 | S17: =IF(OR(Q17="",R17=""),"",SIGN(R17-Q17)*(NETWORKDAYS(MIN(Q17,R17),MAX(Q17,R17))-1)) | T17: =IF(AND(N17>=90%,N17<=100%),"Yes","No") -> Yes | AF17: 10 | AK17: =IF(OR(AI17="",AJ17=""),"",SIGN(AJ17-AI17)*(NETWORKDAYS(MIN(AI17,AJ17),MAX(AI17,AJ17))-1))
A18: 16 | B18: 46210 | C18: ER831 | D18: Pre-Mould Skretting Logo - Red | E18: Carryover | F18: Eruvaka | G18: Carryover - Regular | H18: Mech | I18: r1 | K18: 1 | L18: 46211 | M18: 46211 | N18: 1 | P18: =IF(OR(L18="",M18=""),"",SIGN(M18-L18)*(NETWORKDAYS(MIN(L18,M18),MAX(L18,M18))-1)) -> 0 | S18: =IF(OR(Q18="",R18=""),"",SIGN(R18-Q18)*(NETWORKDAYS(MIN(Q18,R18),MAX(Q18,R18))-1)) | T18: =IF(AND(N18>=90%,N18<=100%),"Yes","No") -> Yes | AF18: 10 | AK18: =IF(OR(AI18="",AJ18=""),"",SIGN(AJ18-AI18)*(NETWORKDAYS(MIN(AI18,AJ18),MAX(AI18,AJ18))-1))
A19: 17 | B19: 46210 | C19: ER789 | D19: SQ125 Rain Cap (Red) | E19: Carryover | F19: Eruvaka | G19: Carryover - Critical | H19: Mech | I19: r1 | K19: 1 | L19: 46211 | M19: 46211 | N19: 1 | P19: =IF(OR(L19="",M19=""),"",SIGN(M19-L19)*(NETWORKDAYS(MIN(L19,M19),MAX(L19,M19))-1)) -> 0 | S19: =IF(OR(Q19="",R19=""),"",SIGN(R19-Q19)*(NETWORKDAYS(MIN(Q19,R19),MAX(Q19,R19))-1)) | T19: =IF(AND(N19>=90%,N19<=100%),"Yes","No") -> Yes | AF19: 10 | AK19: =IF(OR(AI19="",AJ19=""),"",SIGN(AJ19-AI19)*(NETWORKDAYS(MIN(AI19,AJ19),MAX(AI19,AJ19))-1))
A20: 18 | B20: 46210 | C20: ERC092 | D20: Teflon Tape | E20: Carryover | F20: Eruvaka | G20: Carryover - Regular | H20: Mech | I20: r1 | K20: 2 | L20: 46211 | M20: 46211 | N20: 1 | P20: =IF(OR(L20="",M20=""),"",SIGN(M20-L20)*(NETWORKDAYS(MIN(L20,M20),MAX(L20,M20))-1)) -> 0 | S20: =IF(OR(Q20="",R20=""),"",SIGN(R20-Q20)*(NETWORKDAYS(MIN(Q20,R20),MAX(Q20,R20))-1)) | T20: =IF(AND(N20>=90%,N20<=100%),"Yes","No") -> Yes | AF20: 10 | AK20: =IF(OR(AI20="",AJ20=""),"",SIGN(AJ20-AI20)*(NETWORKDAYS(MIN(AI20,AJ20),MAX(AI20,AJ20))-1))
A21: 19 | B21: 46210 | C21: ERC071 | D21: Desiccant Silica Gel | E21: Carryover | F21: Eruvaka | G21: Carryover - Regular | H21: Mech | I21: r1 | K21: 1 | L21: 46211 | M21: 46211 | N21: 1 | P21: =IF(OR(L21="",M21=""),"",SIGN(M21-L21)*(NETWORKDAYS(MIN(L21,M21),MAX(L21,M21))-1)) -> 0 | S21: =IF(OR(Q21="",R21=""),"",SIGN(R21-Q21)*(NETWORKDAYS(MIN(Q21,R21),MAX(Q21,R21))-1)) | T21: =IF(AND(N21>=90%,N21<=100%),"Yes","No") -> Yes | AF21: 10 | AK21: =IF(OR(AI21="",AJ21=""),"",SIGN(AJ21-AI21)*(NETWORKDAYS(MIN(AI21,AJ21),MAX(AI21,AJ21))-1))
A22: 20 | B22: 46210 | C22: ER032 | D22: PG11 (Gland + Lock nut+O ring) | E22: Carryover | F22: Eruvaka | G22: Carryover - Regular | H22: Mech | I22: r1 | K22: =2+4 -> 6 | L22: 46211 | M22: 46211 | N22: 1 | P22: =IF(OR(L22="",M22=""),"",SIGN(M22-L22)*(NETWORKDAYS(MIN(L22,M22),MAX(L22,M22))-1)) -> 0 | S22: =IF(OR(Q22="",R22=""),"",SIGN(R22-Q22)*(NETWORKDAYS(MIN(Q22,R22),MAX(Q22,R22))-1)) | T22: =IF(AND(N22>=90%,N22<=100%),"Yes","No") -> Yes | AF22: 10 | AK22: =IF(OR(AI22="",AJ22=""),"",SIGN(AJ22-AI22)*(NETWORKDAYS(MIN(AI22,AJ22),MAX(AI22,AJ22))-1))
A23: 21 | B23: 46210 | C23: TBA | D23: H- Plate | E23: New | F23: Eruvaka | G23: New - Critical | H23: Mech | I23: r0 | J23: 0 | K23: 1 | L23: 46211 | M23: 46211 | N23: 0.9 | O23: Yes | P23: =IF(OR(L23="",M23=""),"",SIGN(M23-L23)*(NETWORKDAYS(MIN(L23,M23),MAX(L23,M23))-1)) -> 0 | Q23: 46233 | R23: 46218 | S23: =IF(OR(Q23="",R23=""),"",SIGN(R23-Q23)*(NETWORKDAYS(MIN(Q23,R23),MAX(Q23,R23))-1)) -> -11 | T23: =IF(AND(N23>=90%,N23<=100%),"Yes","No") -> Yes | U23: 46234 | V23: 46280 | W23: Feedback from the Supplier - Jig/fixtures needed after samples finalisation before production they will make ready | X23: 46237 | Y23: 46238 | Z23: 46244 | AA23: 46241 | AB23: =AJ23 -> 46290 | AC23: 46241 | AD23: 46262 | AE23: G Industries | AF23: 10 | AG23: 46266 | AH23: Medium | AI23: =IF(OR(AD23="",AH23=""),"",WORKDAY(AD23,IF(AH23="Low",30,IF(AH23="Medium",45,IF(AH23="High",60,""))))) -> 46325 | AJ23: 46290 | AK23: =IF(OR(AI23="",AJ23=""),"",SIGN(AJ23-AI23)*(NETWORKDAYS(MIN(AI23,AJ23),MAX(AI23,AJ23))-1)) -> -25
A24: 22 | B24: 46210 | C24: ERFS070 | D24: M8 Lock washer | E24: Carryover | F24: Eruvaka | G24: Carryover - Regular | H24: Mech | I24: r1 | K24: 4 | L24: 46211 | M24: 46211 | N24: 1 | P24: =IF(OR(L24="",M24=""),"",SIGN(M24-L24)*(NETWORKDAYS(MIN(L24,M24),MAX(L24,M24))-1)) -> 0 | S24: =IF(OR(Q24="",R24=""),"",SIGN(R24-Q24)*(NETWORKDAYS(MIN(Q24,R24),MAX(Q24,R24))-1)) | T24: =IF(AND(N24>=90%,N24<=100%),"Yes","No") -> Yes | AF24: 10 | AK24: =IF(OR(AI24="",AJ24=""),"",SIGN(AJ24-AI24)*(NETWORKDAYS(MIN(AI24,AJ24),MAX(AI24,AJ24))-1))
A25: 23 | B25: 46210 | C25: ER010 | D25: Top Lid | E25: Carryover | F25: Eruvaka | G25: Carryover - Critical | H25: Mech | I25: r1 | K25: 1 | L25: 46211 | M25: 46211 | N25: 1 | P25: =IF(OR(L25="",M25=""),"",SIGN(M25-L25)*(NETWORKDAYS(MIN(L25,M25),MAX(L25,M25))-1)) -> 0 | S25: =IF(OR(Q25="",R25=""),"",SIGN(R25-Q25)*(NETWORKDAYS(MIN(Q25,R25),MAX(Q25,R25))-1)) | T25: =IF(AND(N25>=90%,N25<=100%),"Yes","No") -> Yes | AF25: 10 | AK25: =IF(OR(AI25="",AJ25=""),"",SIGN(AJ25-AI25)*(NETWORKDAYS(MIN(AI25,AJ25),MAX(AI25,AJ25))-1))
A26: 24 | B26: 46210 | C26: ER014 | D26: Knob Handle | E26: Carryover | F26: Eruvaka | G26: Carryover - Regular | H26: Mech | I26: r1 | K26: 1 | L26: 46211 | M26: 46211 | N26: 1 | P26: =IF(OR(L26="",M26=""),"",SIGN(M26-L26)*(NETWORKDAYS(MIN(L26,M26),MAX(L26,M26))-1)) -> 0 | S26: =IF(OR(Q26="",R26=""),"",SIGN(R26-Q26)*(NETWORKDAYS(MIN(Q26,R26),MAX(Q26,R26))-1)) | T26: =IF(AND(N26>=90%,N26<=100%),"Yes","No") -> Yes | AF26: 10 | AK26: =IF(OR(AI26="",AJ26=""),"",SIGN(AJ26-AI26)*(NETWORKDAYS(MIN(AI26,AJ26),MAX(AI26,AJ26))-1))
A27: 25 | B27: 46210 | C27: ERFS007 | D27: M4X10 Hex head bolt | E27: Carryover | F27: Eruvaka | G27: Carryover - Regular | H27: Mech | I27: r1 | K27: 1 | L27: 46211 | M27: 46211 | N27: 1 | P27: =IF(OR(L27="",M27=""),"",SIGN(M27-L27)*(NETWORKDAYS(MIN(L27,M27),MAX(L27,M27))-1)) -> 0 | S27: =IF(OR(Q27="",R27=""),"",SIGN(R27-Q27)*(NETWORKDAYS(MIN(Q27,R27),MAX(Q27,R27))-1)) | T27: =IF(AND(N27>=90%,N27<=100%),"Yes","No") -> Yes | AF27: 10 | AK27: =IF(OR(AI27="",AJ27=""),"",SIGN(AJ27-AI27)*(NETWORKDAYS(MIN(AI27,AJ27),MAX(AI27,AJ27))-1))
A28: 26 | B28: 46210 | C28: ER490 | D28: LID MAGNET ASSY | E28: Carryover | F28: Eruvaka | G28: Carryover - Regular | H28: Mech | I28: r1 | K28: 1 | L28: 46211 | M28: 46211 | N28: 1 | P28: =IF(OR(L28="",M28=""),"",SIGN(M28-L28)*(NETWORKDAYS(MIN(L28,M28),MAX(L28,M28))-1)) -> 0 | S28: =IF(OR(Q28="",R28=""),"",SIGN(R28-Q28)*(NETWORKDAYS(MIN(Q28,R28),MAX(Q28,R28))-1)) | T28: =IF(AND(N28>=90%,N28<=100%),"Yes","No") -> Yes | AF28: 10 | AK28: =IF(OR(AI28="",AJ28=""),"",SIGN(AJ28-AI28)*(NETWORKDAYS(MIN(AI28,AJ28),MAX(AI28,AJ28))-1))
A29: 27 | B29: 46210 | C29: ER088 | D29: Lid Magnet Holder | E29: Carryover | F29: Eruvaka | G29: Carryover - Regular | H29: Mech | I29: r1 | K29: 2 | L29: 46211 | M29: 46211 | N29: 1 | P29: =IF(OR(L29="",M29=""),"",SIGN(M29-L29)*(NETWORKDAYS(MIN(L29,M29),MAX(L29,M29))-1)) -> 0 | S29: =IF(OR(Q29="",R29=""),"",SIGN(R29-Q29)*(NETWORKDAYS(MIN(Q29,R29),MAX(Q29,R29))-1)) | T29: =IF(AND(N29>=90%,N29<=100%),"Yes","No") -> Yes | AF29: 10 | AK29: =IF(OR(AI29="",AJ29=""),"",SIGN(AJ29-AI29)*(NETWORKDAYS(MIN(AI29,AJ29),MAX(AI29,AJ29))-1))
A30: 28 | B30: 46210 | C30: ER086 | D30: Lid Magnet | E30: Carryover | F30: Eruvaka | G30: Carryover - Regular | H30: Mech | I30: r1 | K30: 2 | L30: 46211 | M30: 46211 | N30: 1 | P30: =IF(OR(L30="",M30=""),"",SIGN(M30-L30)*(NETWORKDAYS(MIN(L30,M30),MAX(L30,M30))-1)) -> 0 | S30: =IF(OR(Q30="",R30=""),"",SIGN(R30-Q30)*(NETWORKDAYS(MIN(Q30,R30),MAX(Q30,R30))-1)) | T30: =IF(AND(N30>=90%,N30<=100%),"Yes","No") -> Yes | AF30: 10 | AK30: =IF(OR(AI30="",AJ30=""),"",SIGN(AJ30-AI30)*(NETWORKDAYS(MIN(AI30,AJ30),MAX(AI30,AJ30))-1))
A31: 29 | B31: 46210 | C31: ER085 | D31: Lid Magnet Clamp | E31: Carryover | F31: Eruvaka | G31: Carryover - Regular | H31: Mech | I31: r1 | K31: 2 | L31: 46211 | M31: 46211 | N31: 1 | P31: =IF(OR(L31="",M31=""),"",SIGN(M31-L31)*(NETWORKDAYS(MIN(L31,M31),MAX(L31,M31))-1)) -> 0 | S31: =IF(OR(Q31="",R31=""),"",SIGN(R31-Q31)*(NETWORKDAYS(MIN(Q31,R31),MAX(Q31,R31))-1)) | T31: =IF(AND(N31>=90%,N31<=100%),"Yes","No") -> Yes | AF31: 10 | AK31: =IF(OR(AI31="",AJ31=""),"",SIGN(AJ31-AI31)*(NETWORKDAYS(MIN(AI31,AJ31),MAX(AI31,AJ31))-1))
A32: 30 | B32: 46210 | C32: ER150 | D32: Rivets (4mm Dia x 18mm length) | E32: Carryover | F32: Eruvaka | G32: Carryover - Regular | H32: Mech | I32: r1 | K32: 8 | L32: 46211 | M32: 46211 | N32: 1 | P32: =IF(OR(L32="",M32=""),"",SIGN(M32-L32)*(NETWORKDAYS(MIN(L32,M32),MAX(L32,M32))-1)) -> 0 | S32: =IF(OR(Q32="",R32=""),"",SIGN(R32-Q32)*(NETWORKDAYS(MIN(Q32,R32),MAX(Q32,R32))-1)) | T32: =IF(AND(N32>=90%,N32<=100%),"Yes","No") -> Yes | AF32: 10 | AK32: =IF(OR(AI32="",AJ32=""),"",SIGN(AJ32-AI32)*(NETWORKDAYS(MIN(AI32,AJ32),MAX(AI32,AJ32))-1))
A33: 31 | B33: 46210 | C33: ER151 | D33: Rivet Washer (ID-4.5mm OD-8mm) | E33: Carryover | F33: Eruvaka | G33: Carryover - Regular | H33: Mech | I33: r1 | K33: 8 | L33: 46211 | M33: 46211 | N33: 1 | P33: =IF(OR(L33="",M33=""),"",SIGN(M33-L33)*(NETWORKDAYS(MIN(L33,M33),MAX(L33,M33))-1)) -> 0 | S33: =IF(OR(Q33="",R33=""),"",SIGN(R33-Q33)*(NETWORKDAYS(MIN(Q33,R33),MAX(Q33,R33))-1)) | T33: =IF(AND(N33>=90%,N33<=100%),"Yes","No") -> Yes | AF33: 10 | AK33: =IF(OR(AI33="",AJ33=""),"",SIGN(AJ33-AI33)*(NETWORKDAYS(MIN(AI33,AJ33),MAX(AI33,AJ33))-1))
A34: 32 | B34: 46210 | C34: ERFS048 | D34: M8x100 Hex head bolt | E34: Carryover | F34: Eruvaka | G34: Carryover - Regular | H34: Mech | I34: r1 | K34: 2 | L34: 46211 | M34: 46211 | N34: 1 | P34: =IF(OR(L34="",M34=""),"",SIGN(M34-L34)*(NETWORKDAYS(MIN(L34,M34),MAX(L34,M34))-1)) -> 0 | S34: =IF(OR(Q34="",R34=""),"",SIGN(R34-Q34)*(NETWORKDAYS(MIN(Q34,R34),MAX(Q34,R34))-1)) | T34: =IF(AND(N34>=90%,N34<=100%),"Yes","No") -> Yes | AF34: 10 | AK34: =IF(OR(AI34="",AJ34=""),"",SIGN(AJ34-AI34)*(NETWORKDAYS(MIN(AI34,AJ34),MAX(AI34,AJ34))-1))
A35: 33 | B35: 46210 | C35: ERFS050 | D35: M8 Locknut | E35: Carryover | F35: Eruvaka | G35: Carryover - Regular | H35: Mech | I35: r1 | K35: 2 | L35: 46211 | M35: 46211 | N35: 1 | P35: =IF(OR(L35="",M35=""),"",SIGN(M35-L35)*(NETWORKDAYS(MIN(L35,M35),MAX(L35,M35))-1)) -> 0 | S35: =IF(OR(Q35="",R35=""),"",SIGN(R35-Q35)*(NETWORKDAYS(MIN(Q35,R35),MAX(Q35,R35))-1)) | T35: =IF(AND(N35>=90%,N35<=100%),"Yes","No") -> Yes | AF35: 10 | AK35: =IF(OR(AI35="",AJ35=""),"",SIGN(AJ35-AI35)*(NETWORKDAYS(MIN(AI35,AJ35),MAX(AI35,AJ35))-1))
A36: 34 | B36: 46210 | C36: ER022 | D36: Solar Panel 40 watt | E36: Carryover | F36: Eruvaka | G36: Carryover - Regular | H36: HW | I36: r1 | K36: 1 | L36: 46211 | M36: 46211 | N36: 1 | P36: =IF(OR(L36="",M36=""),"",SIGN(M36-L36)*(NETWORKDAYS(MIN(L36,M36),MAX(L36,M36))-1)) -> 0 | S36: =IF(OR(Q36="",R36=""),"",SIGN(R36-Q36)*(NETWORKDAYS(MIN(Q36,R36),MAX(Q36,R36))-1)) | T36: =IF(AND(N36>=90%,N36<=100%),"Yes","No") -> Yes | AF36: 10 | AK36: =IF(OR(AI36="",AJ36=""),"",SIGN(AJ36-AI36)*(NETWORKDAYS(MIN(AI36,AJ36),MAX(AI36,AJ36))-1))
A37: 35 | B37: 46210 | C37: ERFS017 | D37: M6X20 Hex head bolt | E37: Carryover | F37: Eruvaka | G37: Carryover - Regular | H37: Mech | I37: r1 | K37: =4+6 -> 10 | L37: 46211 | M37: 46211 | N37: 1 | P37: =IF(OR(L37="",M37=""),"",SIGN(M37-L37)*(NETWORKDAYS(MIN(L37,M37),MAX(L37,M37))-1)) -> 0 | S37: =IF(OR(Q37="",R37=""),"",SIGN(R37-Q37)*(NETWORKDAYS(MIN(Q37,R37),MAX(Q37,R37))-1)) | T37: =IF(AND(N37>=90%,N37<=100%),"Yes","No") -> Yes | AF37: 10 | AK37: =IF(OR(AI37="",AJ37=""),"",SIGN(AJ37-AI37)*(NETWORKDAYS(MIN(AI37,AJ37),MAX(AI37,AJ37))-1))
A38: 36 | B38: 46210 | C38: ERFS015 | D38: M6 Washer | E38: Carryover | F38: Eruvaka | G38: Carryover - Regular | H38: Mech | I38: r1 | K38: =8+12 -> 20 | L38: 46211 | M38: 46211 | N38: 1 | P38: =IF(OR(L38="",M38=""),"",SIGN(M38-L38)*(NETWORKDAYS(MIN(L38,M38),MAX(L38,M38))-1)) -> 0 | S38: =IF(OR(Q38="",R38=""),"",SIGN(R38-Q38)*(NETWORKDAYS(MIN(Q38,R38),MAX(Q38,R38))-1)) | T38: =IF(AND(N38>=90%,N38<=100%),"Yes","No") -> Yes | AF38: 10 | AK38: =IF(OR(AI38="",AJ38=""),"",SIGN(AJ38-AI38)*(NETWORKDAYS(MIN(AI38,AJ38),MAX(AI38,AJ38))-1))
A39: 37 | B39: 46210 | C39: ERFS014 | D39: M6 Nut | E39: Carryover | F39: Eruvaka | G39: Carryover - Regular | H39: Mech | I39: r1 | K39: 4 | L39: 46211 | M39: 46211 | N39: 1 | P39: =IF(OR(L39="",M39=""),"",SIGN(M39-L39)*(NETWORKDAYS(MIN(L39,M39),MAX(L39,M39))-1)) -> 0 | S39: =IF(OR(Q39="",R39=""),"",SIGN(R39-Q39)*(NETWORKDAYS(MIN(Q39,R39),MAX(Q39,R39))-1)) | T39: =IF(AND(N39>=90%,N39<=100%),"Yes","No") -> Yes | AF39: 10 | AK39: =IF(OR(AI39="",AJ39=""),"",SIGN(AJ39-AI39)*(NETWORKDAYS(MIN(AI39,AJ39),MAX(AI39,AJ39))-1))
A40: 38 | B40: 46210 | C40: ER786 | D40: SQ125 Solar Panel Mounting Bracket | E40: Carryover | F40: Eruvaka | G40: Carryover - Regular | H40: Mech | I40: r1 | K40: 4 | L40: 46211 | M40: 46211 | N40: 1 | P40: =IF(OR(L40="",M40=""),"",SIGN(M40-L40)*(NETWORKDAYS(MIN(L40,M40),MAX(L40,M40))-1)) -> 0 | S40: =IF(OR(Q40="",R40=""),"",SIGN(R40-Q40)*(NETWORKDAYS(MIN(Q40,R40),MAX(Q40,R40))-1)) | T40: =IF(AND(N40>=90%,N40<=100%),"Yes","No") -> Yes | AF40: 10 | AK40: =IF(OR(AI40="",AJ40=""),"",SIGN(AJ40-AI40)*(NETWORKDAYS(MIN(AI40,AJ40),MAX(AI40,AJ40))-1))
...

Sheet RACI Matrix
A1: Department | B1: Owner | C1: Design Readiness | D1: Part Qualification Readiness | E1: Sourcing Readiness | F1: Supplier Qualification | G1: Sample / Lot Procurement | H1: Factory Handover Readiness
A2: Product Engineering | B2: Mallesha | C2: A | D2: A | E2: C | F2: C | G2: C | H2: A
A3: Design | B3: Ravindra Namburi | C3: R | D3: C | E3: C | F3: C | G3: C | H3: R
A4: HW | B4: Pavan K | C4: R | D4: R | E4: C | F4: C | G4: C | H4: R
A5: FW | B5: Prem | C5: R | D5: C | E5: I | F5: I | G5: I | H5: R
A6: Procurement | B6: Ravindra Kolla | C6: C | D6: C | E6: A/R | F6: S | G6: R | H6: C
A7: Quality | B7: Jeyamurgan | C7: C | D7: A/R | E7: I | F7: R | G7: C | H7: A/R
A8: Production | B8: Venu | C8: C | D8: C | E8: I | F8: C | G8: C | H8: R
A9: Customer Success | B9: Pavan N | C9: C | D9: I | E9: I | F9: I | G9: I | H9: C
A10: V&V | B10: Kiran | C10: C | D10: R | E10: I | F10: C | G10: C | H10: R
A12: R – Responsible | A – Accountable| C – Consulted | I – Informed
A14: Note: | B14: Example

Sheet Timeline
A1: S.No | B1: Readiness Stage | C1: Key Activities / Deliverables | D1: Responsible | E1: Accountable | F1: Planned Start | G1: Target Date | H1: Expected Completion | I1: Actual Completion | J1: Duration (Days) | K1: Days Remaining | L1: Schedule Status | M1: Dependency | N1: Remarks
A2: 1 | B2: Design Readiness | C2: Design freeze approval, final drawings, final BOM, specifications, design review closure | D2: R&D | E2: P&E | G2: 46247 | J2: =IF(OR(F2="",G2=""),"",G2-F2+1) | K2: =IF(H2<>"","",IF(G2="","",G2-TODAY())) -> -43 | L2: =IF(I2<>"","Completed",IF(G2<TODAY(),"Delayed",IF(G2-TODAY()<=7,"At Risk","On Track"))) -> Delayed
A3: 2 | B3: Part Qualification Readiness | C3: Part qualification plan, qualification requirements, identified qualification parts | D3: Quality / V&V | E3: P&E | F3: 46210 | G3: =G2+2 -> 46249 | J3: =IF(OR(F3="",G3=""),"",G3-F3+1) -> 40 | K3: =IF(H3<>"","",IF(G3="","",G3-TODAY())) -> -41 | L3: =IF(I3<>"","Completed",IF(G3<TODAY(),"Delayed",IF(G3-TODAY()<=7,"At Risk","On Track"))) -> Delayed
A4: 3 | B4: Sourcing Readiness | C4: Approved source list, sourcing confirmation, supplier lead time | D4: SCM | E4: P&E | F4: 46234 | G4: 46280 | J4: =IF(OR(F4="",G4=""),"",G4-F4+1) -> 47 | K4: =IF(H4<>"","",IF(G4="","",G4-TODAY())) -> -10 | L4: =IF(I4<>"","Completed",IF(G4<TODAY(),"Delayed",IF(G4-TODAY()<=7,"At Risk","On Track"))) -> Delayed
A5: 4 | B5: Supplier Qualification | C5: Supplier qualification report/approval, supplier evaluation closure | D5: Quality / SCM | E5: Quality | J5: =IF(OR(F5="",G5=""),"",G5-F5+1) | K5: =IF(H5<>"","",IF(G5="","",G5-TODAY())) | L5: =IF(I5<>"","Completed",IF(G5<TODAY(),"Delayed",IF(G5-TODAY()<=7,"At Risk","On Track"))) -> Delayed
A6: 5 | B6: Sample / Lot Procurement | C6: Approved samples/lots received, incoming inspection/verification records | D6: SCM | E6: SCM | J6: =IF(OR(F6="",G6=""),"",G6-F6+1) | K6: =IF(H6<>"","",IF(G6="","",G6-TODAY())) | L6: =IF(I6<>"","Completed",IF(G6<TODAY(),"Delayed",IF(G6-TODAY()<=7,"At Risk","On Track"))) -> Delayed
A7: 6 | B7: Factory Handover Readiness | C7: Final BOM, SOPs, qualification reports, production documents, KT and factory handover | D7: P&E / Quality | E7: P&E | J7: =IF(OR(F7="",G7=""),"",G7-F7+1) | K7: =IF(H7<>"","",IF(G7="","",G7-TODAY())) | L7: =IF(I7<>"","Completed",IF(G7<TODAY(),"Delayed",IF(G7-TODAY()<=7,"At Risk","On Track"))) -> Delayed
B9: Note | C9: Example
